<robot name="robot" version="1.0">
  <joint name="arm1-wrist1_link_joint" type="revolute">
    <limit lower="-3.14000" upper="3.14000" effort="0.00000" velocity="0.00000"/>
    <origin rpy="0.00000 0.00000 0.00000" xyz="-0.00610 -0.20361 1.72510"/>
    <parent link="base_link"/>
    <child link="arm1-wrist1_link"/>
    <axis xyz="0.00000 0.00000 1.00000"/>
  </joint>
  <joint name="arm1-lower-arm_link_joint" type="revolute">
    <limit lower="-3.14000" upper="3.14000" effort="0.00000" velocity="0.00000"/>
    <origin rpy="0.00000 0.00000 0.00000" xyz="0.20740 0.24927 0.19751"/>
    <parent link="arm1-wrist1_link"/>
    <child link="arm1-lower-arm_link"/>
    <axis xyz="-0.64380 -0.76499 -0.01767"/>
  </joint>
  <joint name="arm2-wrist3_link_joint" type="revolute">
    <limit lower="-3.14000" upper="3.14000" effort="0.00000" velocity="0.00000"/>
    <origin rpy="0.00000 -0.00000 -0.00000" xyz="-0.58435 0.49341 0.55420"/>
    <parent link="arm2-upper-arm_link"/>
    <child link="arm2-wrist3_link"/>
    <axis xyz="-0.45622 0.27878 -0.84507"/>
  </joint>
  <joint name="arm2-tool_link_joint" type="revolute">
    <limit lower="-3.14000" upper="3.14000" effort="0.00000" velocity="0.00000"/>
    <origin rpy="0.00000 0.00000 0.00000" xyz="-0.01782 -0.27490 0.10498"/>
    <parent link="arm2-wrist3_link"/>
    <child link="arm2-tool_link"/>
    <axis xyz="0.36743 0.92929 0.03775"/>
  </joint>
  <joint name="base_jointA" type="fixed">
    <origin rpy="-3.14159 -0.00000 -1.74533" xyz="0.00000 0.00000 -1.3000"/>
    <parent link="base_link"/>
    <child link="base_frameA_link"/>
  </joint>
  <joint name="base_jointB" type="fixed">
    <origin rpy="0.00000 0.00000 -1.74533" xyz="0.00000 0.00000 1.3000"/>
    <parent link="base_link"/>
    <child link="base_frameB_link"/>
  </joint>
  <joint name="arm1-wrist2_link_joint" type="revolute">
    <limit lower="-3.14000" upper="3.14000" effort="0.00000" velocity="0.00000"/>
    <origin rpy="0.00000 0.00000 0.00000" xyz="-1.14014 0.65820 0.73462"/>
    <parent link="arm1-lower-arm_link"/>
    <child link="arm1-wrist2_link"/>
    <axis xyz="-0.64380 -0.76499 -0.01767"/>
  </joint>
  <joint name="arm1-upper-arm_link_joint" type="revolute">
    <limit lower="-3.14000" upper="3.14000" effort="0.00000" velocity="0.00000"/>
    <origin rpy="0.00000 0.00000 0.00000" xyz="-0.31274 0.11475 -0.17261"/>
    <parent link="arm1-wrist2_link"/>
    <child link="arm1-upper-arm_link"/>
    <axis xyz="0.67366 -0.55817 0.48439"/>
  </joint>
  <joint name="arm1-wrist3_link_joint" type="revolute">
    <limit lower="-3.14000" upper="3.14000" effort="0.00000" velocity="0.00000"/>
    <origin rpy="0.00000 0.00000 0.00000" xyz="-0.58191 0.50342 -0.54785"/>
    <parent link="arm1-upper-arm_link"/>
    <child link="arm1-wrist3_link"/>
    <axis xyz="-0.46355 0.18542 0.86645"/>
  </joint>
  <joint name="arm1-tool_link_joint" type="revolute">
    <limit lower="-3.14000" upper="3.14000" effort="0.00000" velocity="0.00000"/>
    <origin rpy="0.00000 0.00000 -0.00000" xyz="-0.02087 -0.27051 -0.10962"/>
    <parent link="arm1-wrist3_link"/>
    <child link="arm1-tool_link"/>
    <axis xyz="0.34994 0.93677 -0.00136"/>
  </joint>
  <joint name="arm2-wrist1_link_joint" type="revolute">
    <limit lower="-3.14000" upper="3.14000" effort="0.00000" velocity="0.00000"/>
    <origin rpy="0.00000 0.00000 0.00000" xyz="0.01807 -0.14331 -1.71436"/>
    <parent link="base_link"/>
    <child link="arm2-wrist1_link"/>
    <axis xyz="0.01446 -0.00936 0.99985"/>
  </joint>
  <joint name="arm2-lower-arm_link_joint" type="revolute">
    <limit lower="-3.14000" upper="3.14000" effort="0.00000" velocity="0.00000"/>
    <origin rpy="-0.00000 0.00000 -0.00000" xyz="0.20984 0.25317 -0.18652"/>
    <parent link="arm2-wrist1_link"/>
    <child link="arm2-lower-arm_link"/>
    <axis xyz="-0.63144 -0.77543 0.00000"/>
  </joint>
  <joint name="arm2-wrist2_link_joint" type="revolute">
    <limit lower="-3.14000" upper="3.14000" effort="0.00000" velocity="0.00000"/>
    <origin rpy="-0.00000 0.00000 -0.00000" xyz="-1.12976 0.68237 -0.72754"/>
    <parent link="arm2-lower-arm_link"/>
    <child link="arm2-wrist2_link"/>
    <axis xyz="-0.63144 -0.77543 0.00000"/>
  </joint>
  <joint name="arm2-upper-arm_link_joint" type="revolute">
    <limit lower="-3.14000" upper="3.14000" effort="0.00000" velocity="0.00000"/>
    <origin rpy="-0.00000 0.00000 -0.00000" xyz="-0.32092 0.09888 0.17334"/>
    <parent link="arm2-wrist2_link"/>
    <child link="arm2-upper-arm_link"/>
    <axis xyz="0.68742 -0.54399 -0.48116"/>
  </joint>
  <link name="base_link">
    <visual name="base">
      <material name="white"/>
      <origin rpy="0.00000 0.00000 0.00000" xyz="0.00000 0.00000 0.00000"/>
      <geometry>
        <mesh filename="../meshes/stl/base_link.stl" scale="1.00000 1.00000 1.00000"/>
      </geometry>
    </visual>
  </link>
  <link name="arm1-wrist1_link">
    <visual name="arm1-wrist1">
      <material name="white"/>
      <origin rpy="0.00000 0.00000 0.00000" xyz="0.00000 0.00000 0.00000"/>
      <geometry>
        <mesh filename="../meshes/stl/arm1-wrist1_link.stl" scale="1.00000 1.00000 1.00000"/>
      </geometry>
    </visual>
  </link>
  <link name="arm2-upper-arm_link">
    <visual name="arm2-upper-arm">
      <material name="white"/>
      <origin rpy="0.00000 -0.00000 -0.00000" xyz="0.00012 0.00000 0.00000"/>
      <geometry>
        <mesh filename="../meshes/stl/arm2-upper-arm_link.stl" scale="1.00000 1.00000 1.00000"/>
      </geometry>
    </visual>
  </link>
  <link name="arm2-wrist3_link">
    <visual name="arm2-wrist3">
      <material name="white"/>
      <origin rpy="0.00000 0.00000 0.00000" xyz="0.00012 0.00000 -0.00000"/>
      <geometry>
        <mesh filename="../meshes/stl/arm2-wrist3_link.stl" scale="1.00000 1.00000 1.00000"/>
      </geometry>
    </visual>
  </link>
  <link name="arm2-tool_link">
    <visual name="arm2-tool">
      <material name="white"/>
      <origin rpy="-0.00000 -0.00000 0.00000" xyz="0.00012 -0.00024 0.00000"/>
      <geometry>
        <mesh filename="../meshes/stl/arm2-tool_link.stl" scale="1.00000 1.00000 1.00000"/>
      </geometry>
    </visual>
  </link>
  <link name="base_frameA_link"/>
  <link name="base_frameB_link"/>
  <link name="arm1-lower-arm_link">
    <visual name="arm1-lower-arm">
      <material name="white"/>
      <origin rpy="0.00000 0.00000 0.00000" xyz="0.00000 0.00024 0.00000"/>
      <geometry>
        <mesh filename="../meshes/stl/arm1-lower-arm_link.stl" scale="1.00000 1.00000 1.00000"/>
      </geometry>
    </visual>
  </link>
  <link name="arm1-wrist2_link">
    <visual name="arm1-wrist2">
      <material name="white"/>
      <origin rpy="0.00000 0.00000 0.00000" xyz="0.00000 0.00000 0.00000"/>
      <geometry>
        <mesh filename="../meshes/stl/arm1-wrist2_link.stl" scale="1.00000 1.00000 1.00000"/>
      </geometry>
    </visual>
  </link>
  <link name="arm1-upper-arm_link">
    <visual name="arm1-upper-arm">
      <material name="white"/>
      <origin rpy="0.00000 0.00000 0.00000" xyz="0.00000 -0.00000 0.00000"/>
      <geometry>
        <mesh filename="../meshes/stl/arm1-upper-arm_link.stl" scale="1.00000 1.00000 1.00000"/>
      </geometry>
    </visual>
  </link>
  <link name="arm1-wrist3_link">
    <visual name="arm1-wrist3">
      <material name="white"/>
      <origin rpy="0.00000 0.00000 -0.00000" xyz="-0.00012 0.00024 -0.00000"/>
      <geometry>
        <mesh filename="../meshes/stl/arm1-wrist3_link.stl" scale="1.00000 1.00000 1.00000"/>
      </geometry>
    </visual>
  </link>
  <link name="arm1-tool_link">
    <visual name="arm1-tool">
      <material name="white"/>
      <origin rpy="0.00000 -0.00000 -0.00000" xyz="-0.00000 0.00024 -0.00000"/>
      <geometry>
        <mesh filename="../meshes/stl/arm1-tool_link.stl" scale="1.00000 1.00000 1.00000"/>
      </geometry>
    </visual>
  </link>
  <link name="arm2-wrist1_link">
    <visual name="arm2-wrist1">
      <material name="white"/>
      <origin rpy="-0.00000 0.00000 -0.00000" xyz="0.00000 0.00000 0.00000"/>
      <geometry>
        <mesh filename="../meshes/stl/arm2-wrist1_link.stl" scale="1.00000 1.00000 1.00000"/>
      </geometry>
    </visual>
  </link>
  <link name="arm2-lower-arm_link">
    <visual name="arm2-lower-arm">
      <material name="white"/>
      <origin rpy="-0.00000 0.00000 -0.00000" xyz="0.00012 0.00000 0.00024"/>
      <geometry>
        <mesh filename="../meshes/stl/arm2-lower-arm_link.stl" scale="1.00000 1.00000 1.00000"/>
      </geometry>
    </visual>
  </link>
  <link name="arm2-wrist2_link">
    <visual name="arm2-wrist2">
      <material name="white"/>
      <origin rpy="-0.00000 0.00000 -0.00000" xyz="-0.00000 -0.00000 0.00000"/>
      <geometry>
        <mesh filename="../meshes/stl/arm2-wrist2_link.stl" scale="1.00000 1.00000 1.00000"/>
      </geometry>
    </visual>
  </link>
  <material name="white">
    <color rgba="1.00000 1.00000 1.00000 1.00000"/>
  </material>
</robot>
